<?xml version="1.0" encoding="UTF-8"?>
<testsuites name="Mocha Tests" time="3.838" tests="8" failures="7">
  <testsuite name="Root Suite" timestamp="2020-09-17T19:23:28" tests="0" failures="0" time="0">
  </testsuite>
  <testsuite name="city search test" timestamp="2020-09-17T19:23:28" tests="8" file="/projects/challenge/test/test.js" failures="7" time="3.838">
    <testcase name="city search test Valid input should be provided in the input box - no space no numbers allowed" time="0.335" classname="Valid input should be provided in the input box - no space no numbers allowed">
      <failure message="expected &apos;Please provide a valid input (only characters A-Z or a-z)&apos; to equal &apos;Please provide the valid input&apos;" type="AssertionError"><![CDATA[AssertionError: expected 'Please provide a valid input (only characters A-Z or a-z)' to equal 'Please provide the valid input'
    at Context.<anonymous> (test/test.js:61:30)
    at <anonymous>
    at process._tickCallback (internal/process/next_tick.js:189:7)]]></failure>
    </testcase>
    <testcase name="city search test After typing invalid input, it should be reset" time="0.211" classname="After typing invalid input, it should be reset">
    </testcase>
    <testcase name="city search test Should search cities and render table on valid input by making sure api is hit" time="0.65" classname="Should search cities and render table on valid input by making sure api is hit">
      <failure message="expected &apos;&apos; to equal &apos;Total cities found: 10&apos;" type="AssertionError"><![CDATA[AssertionError: expected '' to equal 'Total cities found: 10'
    at Context.<anonymous> (test/test.js:158:26)
    at <anonymous>
    at process._tickCallback (internal/process/next_tick.js:189:7)]]></failure>
    </testcase>
    <testcase name="city search test Should give correct result when no data is returned by the api" time="0.603" classname="Should give correct result when no data is returned by the api">
      <failure message="expected 1 to equal 0" type="AssertionError"><![CDATA[AssertionError: expected 1 to equal 0
    at Context.<anonymous> (test/test.js:211:36)
    at <anonymous>
    at process._tickCallback (internal/process/next_tick.js:189:7)]]></failure>
    </testcase>
    <testcase name="city search test Should give correct result when data is returned by the api - test 1" time="0.505" classname="Should give correct result when data is returned by the api - test 1">
      <failure message="expected 10 to equal 9" type="AssertionError"><![CDATA[AssertionError: expected 10 to equal 9
    at Context.<anonymous> (test/test.js:262:36)
    at <anonymous>
    at process._tickCallback (internal/process/next_tick.js:189:7)]]></failure>
    </testcase>
    <testcase name="city search test Should give correct result when data is returned by the api - test 2" time="0.492" classname="Should give correct result when data is returned by the api - test 2">
      <failure message="expected 10 to equal 9" type="AssertionError"><![CDATA[AssertionError: expected 10 to equal 9
    at Context.<anonymous> (test/test.js:313:36)
    at <anonymous>
    at process._tickCallback (internal/process/next_tick.js:189:7)]]></failure>
    </testcase>
    <testcase name="city search test Should give correct result when data is returned by the api - test 3" time="0.56" classname="Should give correct result when data is returned by the api - test 3">
      <failure message="expected 1 to equal 0" type="AssertionError"><![CDATA[AssertionError: expected 1 to equal 0
    at Context.<anonymous> (test/test.js:364:36)
    at <anonymous>
    at process._tickCallback (internal/process/next_tick.js:189:7)]]></failure>
    </testcase>
    <testcase name="city search test Should give correct result when data is returned by the api - test 4" time="0.482" classname="Should give correct result when data is returned by the api - test 4">
      <failure message="expected 1 to equal 0" type="AssertionError"><![CDATA[AssertionError: expected 1 to equal 0
    at Context.<anonymous> (test/test.js:415:36)
    at <anonymous>
    at process._tickCallback (internal/process/next_tick.js:189:7)]]></failure>
    </testcase>
  </testsuite>
</testsuites>